<?xml version="1.0" ?>
<!-- =================================================================================== -->
<!-- |    This document was autogenerated by xacro from robot.urdf.xacro               | -->
<!-- |    EDITING THIS FILE BY HAND IS NOT RECOMMENDED                                 | -->
<!-- =================================================================================== -->
<robot name="proj_dd">
  <!-- Xacro -->
  <!-- Bot -->
  <!-- Body -->
  <link name="base_link">
    <visual>
      <geometry>
        <cylinder length="0.3" radius="0.2"/>
      </geometry>
      <origin rpy="0 0 0" xyz="0 0 0.2"/>
      <material name="lime">
        <color rgba="0.3 0.6 0 1"/>
      </material>
    </visual>
    <collision>
      <geometry>
        <cylinder length="0.3" radius="0.2"/>
      </geometry>
      <origin rpy="0 0 0" xyz="0 0 0.2"/>
    </collision>
    <inertial>
      <origin rpy="0.0 0.0 0.0" xyz="0.0 0.0 0.0"/>
      <mass value="20.0"/>
      <inertia ixx="0.35" ixy="0.0" ixz="0.0" iyy="0.35" iyz="0.0" izz="0.4"/>
    </inertial>
  </link>
  <link name="body">
    <visual>
      <geometry>
        <box size="0.2 0.2 0.35"/>
      </geometry>
      <origin rpy="0 0 0" xyz="0 0 0"/>
      <material name="lime">
        <color rgba="0.3 0.6 0 1"/>
      </material>
    </visual>
    <collision>
      <geometry>
        <box size="0.2 0.2 0.35"/>
      </geometry>
      <origin rpy="0 0 0" xyz="0 0 0"/>
    </collision>
    <inertial>
      <origin rpy="0.0 0.0 0.0" xyz="0.0 0.0 0.0"/>
      <mass value="3.0"/>
      <inertia ixx="0.041" ixy="0.0" ixz="0.0" iyy="0.041" iyz="0.0" izz="0.02"/>
    </inertial>
  </link>
  <joint name="base_to_body" type="fixed">
    <parent link="base_link"/>
    <child link="body"/>
    <origin rpy="0 0 0" xyz="0 0.0 0.525"/>
  </joint>
  <link name="head">
    <visual>
      <geometry>
        <box size="0.3 0.3 0.3"/>
      </geometry>
      <origin rpy="0 0 0" xyz="0 0 0"/>
      <material name="lime">
        <color rgba="0.3 0.6 0 1"/>
      </material>
    </visual>
    <collision>
      <geometry>
        <box size="0.3 0.3 0.3"/>
      </geometry>
      <origin rpy="0 0 0" xyz="0 0 0"/>
    </collision>
    <inertial>
      <origin rpy="0.0 0.0 0.0" xyz="0.0 0.0 0.0"/>
      <mass value="2.0"/>
      <inertia ixx="0.03" ixy="0.0" ixz="0.0" iyy="0.03" iyz="0.0" izz="0.03"/>
    </inertial>
  </link>
  <joint name="body_to_head" type="revolute">
    <parent link="body"/>
    <child link="head"/>
    <origin rpy="0 0 0" xyz="0 0.0 0.325"/>
    <axis xyz="0.0 0.0 1.0"/>
    <limit effort="1000.0" lower="-3.1416" upper="3.1416" velocity="0.5"/>
  </joint>
  <!-- Drive wheel -->
  <link name="lwheel">
    <visual>
      <geometry>
        <cylinder length="0.1" radius="0.2"/>
      </geometry>
      <origin rpy="0 0 0" xyz="0 0 0"/>
      <material name="black">
        <color rgba="0 0 0 1"/>
      </material>
    </visual>
    <collision>
      <geometry>
        <cylinder length="0.1" radius="0.2"/>
      </geometry>
      <origin rpy="0 0 0" xyz="0 0 0"/>
    </collision>
    <inertial>
      <origin rpy="0.0 0.0 0.0" xyz="0.0 0.0 0.0"/>
      <mass value="2.0"/>
      <inertia ixx="0.022" ixy="0.0" ixz="0.0" iyy="0.022" iyz="0.0" izz="0.04"/>
    </inertial>
  </link>
  <joint name="base_to_lwheel" type="continuous">
    <parent link="base_link"/>
    <child link="lwheel"/>
    <axis xyz="0.0 0.0 1.0"/>
    <limit effort="100.0" velocity="100.0"/>
    <joint_properties damping="0.0" friction="0.0"/>
    <origin rpy="-1.5708 0 0" xyz="0 0.25 0.2"/>
  </joint>
  <link name="lwheel_box">
    <visual>
      <geometry>
        <box size="0.1 0.01 0.1"/>
      </geometry>
      <origin rpy="0 0 0" xyz="0 0 0"/>
      <material name="white">
        <color rgba="1 1 1 1"/>
      </material>
    </visual>
    <inertial>
      <origin rpy="0.0 0.0 0.0" xyz="0.0 0.0 0.0"/>
      <mass value="0.5"/>
      <inertia ixx="0.0004" ixy="0.0" ixz="0.0" iyy="0.0008" iyz="0.0" izz="0.0004"/>
    </inertial>
  </link>
  <joint name="lwheel_to_lwheel_box" type="fixed">
    <parent link="lwheel"/>
    <child link="lwheel_box"/>
    <origin rpy="1.5708 0 0" xyz="0 0 0.055"/>
  </joint>
  <link name="rwheel">
    <visual>
      <geometry>
        <cylinder length="0.1" radius="0.2"/>
      </geometry>
      <origin rpy="0 0 0" xyz="0 0 0"/>
      <material name="black">
        <color rgba="0 0 0 1"/>
      </material>
    </visual>
    <collision>
      <geometry>
        <cylinder length="0.1" radius="0.2"/>
      </geometry>
      <origin rpy="0 0 0" xyz="0 0 0"/>
    </collision>
    <inertial>
      <origin rpy="0 0 0" xyz="0.0 0.0 0.0"/>
      <mass value="2.0"/>
      <inertia ixx="0.022" ixy="0.0" ixz="0.0" iyy="0.022" iyz="0.0" izz="0.04"/>
    </inertial>
  </link>
  <joint name="base_to_rwheel" type="continuous">
    <parent link="base_link"/>
    <child link="rwheel"/>
    <axis xyz="0.0 0.0 1.0"/>
    <limit effort="100.0" velocity="100.0"/>
    <joint_properties damping="0.0" friction="0.0"/>
    <origin rpy="-1.5708 0 0" xyz="0 -0.25 0.2"/>
  </joint>
  <link name="rwheel_box">
    <visual>
      <geometry>
        <box size="0.1 0.01 0.1"/>
      </geometry>
      <origin rpy="0 0 0" xyz="0 0 0"/>
      <material name="white">
        <color rgba="1 1 1 1"/>
      </material>
    </visual>
    <collision>
      <geometry>
        <box size="0.1 0.01 0.1"/>
      </geometry>
      <origin rpy="0 0 0" xyz="0 0 0"/>
    </collision>
    <inertial>
      <origin rpy="0.0 0.0 0.0" xyz="0.0 0.0 0.0"/>
      <mass value="0.5"/>
      <inertia ixx="0.0004" ixy="0.0" ixz="0.0" iyy="0.0008" iyz="0.0" izz="0.0004"/>
    </inertial>
  </link>
  <joint name="rwheel_to_rwheel_box" type="fixed">
    <parent link="rwheel"/>
    <child link="rwheel_box"/>
    <origin rpy="1.5708 0 0" xyz="0 0 -0.055"/>
  </joint>
  <!-- Balance wheel -->
  <link name="fwheel_attach">
    <visual>
      <geometry>
        <box size="0.05 0.05 0.1"/>
      </geometry>
      <origin rpy="0 0 0" xyz="0 0 0"/>
      <material name="lime">
        <color rgba="0.3 0.6 0 1"/>
      </material>
    </visual>
    <collision>
      <geometry>
        <box size="0.05 0.05 0.1"/>
      </geometry>
      <origin rpy="0 0 0" xyz="0 0 0"/>
    </collision>
    <inertial>
      <origin rpy="0.0 0.0 0.0" xyz="0.0 0.0 0.0"/>
      <mass value="0.5"/>
      <inertia ixx="0.0005" ixy="0.0" ixz="0.0" iyy="0.0005" iyz="0.0" izz="0.0002"/>
    </inertial>
  </link>
  <joint name="base_to_fattach" type="fixed">
    <parent link="base_link"/>
    <child link="fwheel_attach"/>
    <origin rpy="0 0 0" xyz="0.225 0 0.1"/>
  </joint>
  <link name="fwheel">
    <visual>
      <geometry>
        <sphere radius="0.025"/>
      </geometry>
      <origin rpy="0 0 0" xyz="0 0 0"/>
      <material name="black">
        <color rgba="0 0 0 1"/>
      </material>
    </visual>
    <collision>
      <geometry>
        <sphere radius="0.025"/>
      </geometry>
      <origin rpy="0 0 0" xyz="0 0 0"/>
    </collision>
    <inertial>
      <origin rpy="0.0 0.0 0.0" xyz="0.0 0.0 0.0"/>
      <mass value="0.5"/>
      <inertia ixx="0.0001" ixy="0.0" ixz="0.0" iyy="0.0001" iyz="0.0" izz="0.0001"/>
    </inertial>
  </link>
  <joint name="fwheel_attach_to_fwheel" type="continuous">
    <parent link="fwheel_attach"/>
    <child link="fwheel"/>
    <origin rpy="0 0 0" xyz="0 0 -0.075"/>
    <axis xyz="1.0 1.0 1.0"/>
    <limit effort="100.0" velocity="100.0"/>
    <joint_properties damping="0.0" friction="0.0"/>
  </joint>
  <link name="bwheel_attach">
    <visual>
      <geometry>
        <box size="0.05 0.05 0.1"/>
      </geometry>
      <origin rpy="0 0 0" xyz="0 0 0"/>
      <material name="lime">
        <color rgba="0.3 0.6 0 1"/>
      </material>
    </visual>
    <collision>
      <geometry>
        <box size="0.05 0.05 0.1"/>
      </geometry>
      <origin rpy="0 0 0" xyz="0 0 0"/>
    </collision>
    <inertial>
      <origin rpy="0.0 0.0 0.0" xyz="0.0 0.0 0.0"/>
      <mass value="0.5"/>
      <inertia ixx="0.0005" ixy="0.0" ixz="0.0" iyy="0.0005" iyz="0.0" izz="0.0002"/>
    </inertial>
  </link>
  <joint name="base_to_battach" type="fixed">
    <parent link="base_link"/>
    <child link="bwheel_attach"/>
    <origin rpy="0 0 0" xyz="-0.225 0 0.1"/>
  </joint>
  <link name="bwheel">
    <visual>
      <geometry>
        <sphere radius="0.025"/>
      </geometry>
      <origin rpy="0 0 0" xyz="0 0 0"/>
      <material name="black">
        <color rgba="0 0 0 1"/>
      </material>
    </visual>
    <collision>
      <geometry>
        <sphere radius="0.025"/>
      </geometry>
      <origin rpy="0 0 0" xyz="0 0 0"/>
    </collision>
    <inertial>
      <origin rpy="0.0 0.0 0.0" xyz="0.0 0.0 0.0"/>
      <mass value="0.5"/>
      <inertia ixx="0.0001" ixy="0.0" ixz="0.0" iyy="0.0001" iyz="0.0" izz="0.0001"/>
    </inertial>
  </link>
  <joint name="bwheel_attach_to_bwheel" type="fixed">
    <parent link="bwheel_attach"/>
    <child link="bwheel"/>
    <origin rpy="0 0 0" xyz="0 0 -0.075"/>
    <axis xyz="1.0 1.0 1.0"/>
    <limit effort="100.0" velocity="100.0"/>
    <joint_properties damping="0.0" friction="0.0"/>
  </joint>
  <!-- Camera -->
  <link name="camera">
    <visual>
      <geometry>
        <cylinder length="0.3" radius="0.025"/>
      </geometry>
      <origin rpy="0 0 0" xyz="0 0 0"/>
      <material name="black">
        <color rgba="0 0 0 1"/>
      </material>
    </visual>
    <collision>
      <geometry>
        <cylinder length="0.3" radius="0.025"/>
      </geometry>
      <origin rpy="0 0 0" xyz="0 0 0"/>
    </collision>
    <inertial>
      <origin rpy="0.0 0.0 0.0" xyz="0.0 0.0 0.0"/>
      <mass value="0.1"/>
      <inertia ixx="0.0008" ixy="0.0" ixz="0.0" iyy="0.0008" iyz="0.0" izz="0.00003"/>
    </inertial>
  </link>
  <joint name="head_to_camera" type="revolute">
    <parent link="head"/>
    <child link="camera"/>
    <origin rpy="1.5708 0 0" xyz="0.175 0 0.075"/>
    <axis xyz="0.0 0.0 1.0"/>
    <limit effort="1000.0" lower="-1.0472" upper="1.0472" velocity="0.5"/>
  </joint>
  <link name="lens">
    <visual>
      <geometry>
        <box size="0.01 0.025 0.025"/>
      </geometry>
      <origin rpy="0 0 0" xyz="0 0 0"/>
      <material name="white">
        <color rgba="1 1 1 1"/>
      </material>
    </visual>
    <collision>
      <geometry>
        <box size="0.1 0.01 0.1"/>
      </geometry>
      <origin rpy="0 0 0" xyz="0 0 0"/>
    </collision>
    <inertial>
      <origin rpy="0.0 0.0 0.0" xyz="0.0 0.0 0.0"/>
      <mass value="0.05"/>
      <inertia ixx="0.000005" ixy="0.0" ixz="0.0" iyy="0.000003" iyz="0.0" izz="0.000003"/>
    </inertial>
  </link>
  <joint name="camera_to_lens" type="fixed">
    <parent link="camera"/>
    <child link="lens"/>
    <origin rpy="-1.5708 0 0" xyz="0.03 0 0"/>
  </joint>
  <!-- transmission -->
  <transmission name="cam_trans">
    <type>transmission_interface/SimpleTransmission</type>
    <actuator name="motor1">
      <mechanicalReduction>1</mechanicalReduction>
    </actuator>
    <joint name="head_to_camera">
      <hardwareInterface>EffortJointInterface</hardwareInterface>
    </joint>
  </transmission>
  <transmission name="head_trans">
    <type>transmission_interface/SimpleTransmission</type>
    <actuator name="motor2">
      <mechanicalReduction>1</mechanicalReduction>
    </actuator>
    <joint name="body_to_head">
      <hardwareInterface>EffortJointInterface</hardwareInterface>
    </joint>
  </transmission>
  <transmission name="left_wheel_transmission">
    <type>transmission_interface/SimpleTransmission</type>
    <joint name="base_to_lwheel">
      <hardwareInterface>hardware_interface/VelocityJointInterface</hardwareInterface>
    </joint>
    <actuator name="left_wheel_actuator">
      <mechanicalReduction>7</mechanicalReduction>
      <hardwareInterface>VelocityJointInterface</hardwareInterface>
    </actuator>
  </transmission>
  <transmission name="right_wheel_transmission">
    <type>transmission_interface/SimpleTransmission</type>
    <joint name="base_to_rwheel">
      <hardwareInterface>hardware_interface/VelocityJointInterface</hardwareInterface>
    </joint>
    <actuator name="right_wheel_actuator">
      <mechanicalReduction>7</mechanicalReduction>
      <hardwareInterface>VelocityJointInterface</hardwareInterface>
    </actuator>
  </transmission>
  <!-- camera -->
  <gazebo reference="lens">
    <sensor name="camera1" type="camera">
      <update_rate>30.0</update_rate>
      <camera name="head">
        <horizontal_fov>1.3962634</horizontal_fov>
        <image>
          <width>800</width>
          <height>800</height>
          <format>R8G8B8</format>
        </image>
        <clip>
          <near>0.02</near>
          <far>300</far>
        </clip>
      </camera>
      <plugin filename="libgazebo_ros_camera.so" name="camera_controller">
        <alwaysOn>true</alwaysOn>
        <updateRate>0.0</updateRate>
        <cameraName>robot/camera1</cameraName>
        <imageTopicName>image_raw</imageTopicName>
        <cameraInfoTopicName>camera_info</cameraInfoTopicName>
        <frameName>lens</frameName>
        <hackBaseline>0.07</hackBaseline>
        <distortionK1>0.0</distortionK1>
        <distortionK2>0.0</distortionK2>
        <distortionK3>0.0</distortionK3>
        <distortionT1>0.0</distortionT1>
        <distortionT2>0.0</distortionT2>
      </plugin>
    </sensor>
  </gazebo>
  <!-- ROS Control plugin for Gazebo -->
  <gazebo>
    <plugin filename="libgazebo_ros_control.so" name="gazebo_ros_control">
      <robotNamespace>/simple_model</robotNamespace>
    </plugin>
    <plugin filename="libgazebo_ros_diff_drive.so" name="differential_drive_controller">
      <updateRate>10</updateRate>
      <leftJoint>base_to_lwheel</leftJoint>
      <rightJoint>base_to_rwheel</rightJoint>
      <wheelSeparation>0.5</wheelSeparation>
      <wheelDiameter>0.4</wheelDiameter>
      <wheelAcceleration>10.0</wheelAcceleration>
      <wheelTorque>10</wheelTorque>
      <odometryTopic>odom</odometryTopic>
      <odometryFrame>odom</odometryFrame>
      <robotBaseFrame>base_link</robotBaseFrame>
      <odometrySource>1</odometrySource>
      <publishWheelTF>true</publishWheelTF>
      <publishOdom>true</publishOdom>
      <publishWheelJointState>true</publishWheelJointState>
      <legacyMode>false</legacyMode>
      <alwaysOn>true</alwaysOn>
    </plugin>
  </gazebo>
  <!-- Material -->
  <gazebo reference="base_link">
    <material>
      Gazebo/Green
    </material>
  </gazebo>
  <gazebo reference="body">
    <material>
      Gazebo/Green
    </material>
  </gazebo>
  <gazebo reference="head">
    <material>
      Gazebo/Green
    </material>
  </gazebo>
  <gazebo reference="fwheel_attach">
    <material>
      Gazebo/Green
    </material>
  </gazebo>
  <gazebo reference="bwheel_attach">
    <material>
      Gazebo/Green
    </material>
  </gazebo>
  <gazebo reference="fwheel">
    <material>
      Gazebo/Black
    </material>
  </gazebo>
  <gazebo reference="bwheel">
    <material>
      Gazebo/Black
    </material>
  </gazebo>
  <gazebo reference="camera">
    <material>
      Gazebo/Black
    </material>
  </gazebo>
  <gazebo reference="lwheel_box">
    <material>
      Gazebo/White
    </material>
  </gazebo>
  <gazebo reference="rwheel_box">
    <material>
      Gazebo/White
    </material>
  </gazebo>
  <gazebo reference="lwheel">
    <material>
      Gazebo/Black
    </material>
  </gazebo>
  <gazebo reference="rwheel">
    <material>
      Gazebo/Black
    </material>
  </gazebo>
</robot>
