<?xml version="1.0"?>
<robot name="proj_dd" xmlns:xacro="http://www.ros.org/wiki/xacro">

<!-- Xacro -->

<xacro:property name="base_r" value="0.2"/>
<xacro:property name="wheel_t" value="0.1"/>
<xacro:property name="wheel_r" value="0.2"/>

<!-- Bot -->

<!-- Body -->

  <link name="base_link">
    <visual>
      <geometry>
        <cylinder radius="${base_r}" length="0.3"/>
      </geometry>
      <origin rpy="0 0 0" xyz="0 0 0.2"/>
      <material name="lime">
        <color rgba="0.3 0.6 0 1"/>
      </material>
    </visual>
    <collision>
      <geometry>
        <cylinder radius="${base_r}" length="0.3"/>
      </geometry>
      <origin rpy="0 0 0" xyz="0 0 0.2"/>
    </collision>
    <inertial>
      <origin xyz="0.0 0.0 0.0" rpy="0.0 0.0 0.0"/>
      <mass value="10.0"/>
      <inertia ixx="0.175" ixy="0.0" ixz="0.0" iyy="0.175" iyz="0.0" izz="0.2"/>
    </inertial>
    
  </link>

  <link name="body">
    <visual>
      <geometry>
        <box size="0.2 0.2 0.35"/>
      </geometry>
      <origin rpy="0 0 0" xyz="0 0 0"/>
      <material name="lime">
        <color rgba="0.3 0.6 0 1"/>
      </material>
    </visual>
    <collision>
      <geometry>
        <box size="0.2 0.2 0.35"/>
      </geometry>
      <origin rpy="0 0 0" xyz="0 0 0"/>
    </collision>
    <inertial>
      <origin xyz="0.0 0.0 0.0" rpy="0.0 0.0 0.0"/>
      <mass value="3.0"/>
      <inertia ixx="0.041" ixy="0.0" ixz="0.0" iyy="0.041" iyz="0.0" izz="0.02"/>
    </inertial>
    
  </link>
  
  <joint name="base_to_body" type="fixed">
    <parent link="base_link"/>
    <child link="body"/>
    <origin xyz="0 0.0 0.525" rpy="0 0 0"/>
  </joint>

  <link name="head">
    <visual>
      <geometry>
        <box size="0.3 0.3 0.3"/>
      </geometry>
      <origin rpy="0 0 0" xyz="0 0 0"/>
      <material name="lime">
        <color rgba="0.3 0.6 0 1"/>
      </material>
    </visual>
    <collision>
      <geometry>
        <box size="0.3 0.3 0.3"/>
      </geometry>
      <origin rpy="0 0 0" xyz="0 0 0"/>
    </collision>
    <inertial>
      <origin xyz="0.0 0.0 0.0" rpy="0.0 0.0 0.0"/>
      <mass value="2.0"/>
      <inertia ixx="0.03" ixy="0.0" ixz="0.0" iyy="0.03" iyz="0.0" izz="0.03"/>
    </inertial>
    
  </link>
  
  <joint name="body_to_head" type="revolute">
    <parent link="body"/>
    <child link="head"/>
    <origin xyz="0 0.0 0.325" rpy="0 0 0"/>
    <axis xyz="0.0 0.0 1.0"/>
    <limit lower="-3.1416" upper="3.1416" effort="1000.0" velocity="0.5"/>
  </joint>

<!-- Drive wheel -->

  <link name="lwheel">
    <visual>
      <geometry>
        <cylinder length="${wheel_t}" radius="${wheel_r}"/>
      </geometry>
      <origin rpy="0 0 0" xyz="0 0 0"/>
      <material name="black">
        <color rgba="0 0 0 1"/>
      </material>
    </visual>
    <collision>
      <geometry>
        <cylinder length="${wheel_t}" radius="${wheel_r}"/>
      </geometry>
      <origin rpy="0 0 0" xyz="0 0 0"/>
    </collision>
    <inertial>
      <origin xyz="0.0 0.0 0.0" rpy="0.0 0.0 0.0"/>
      <mass value="2.0"/>
      <inertia ixx="0.022" ixy="0.0" ixz="0.0" iyy="0.022" iyz="0.0" izz="0.04"/>
    </inertial>
    
  </link>
  
  <joint name="base_to_lwheel" type="continuous">
    <parent link="base_link"/>
    <child link="lwheel"/>
    <axis xyz="0.0 0.0 1.0"/>
    <limit effort="100.0" velocity="100.0"/>
    <joint_properties damping="0.0" friction="0.0"/>
    <origin xyz="0 0.25 0.2" rpy="-1.5708 0 0"/>
  </joint>
  
  <link name="rwheel">
    <visual>
      <geometry>
        <cylinder length="${wheel_t}" radius="${wheel_r}"/>
      </geometry>
      <origin rpy="0 0 0" xyz="0 0 0"/>
      <material name="black">
        <color rgba="0 0 0 1"/>
      </material>
    </visual>
    <collision>
      <geometry>
        <cylinder length="${wheel_t}" radius="${wheel_r}"/>
      </geometry>
      <origin rpy="0 0 0" xyz="0 0 0"/>
    </collision>
    <inertial>
      <origin xyz="0.0 0.0 0.0" rpy="0 0 0"/>
      <mass value="2.0"/>
      <inertia ixx="0.022" ixy="0.0" ixz="0.0" iyy="0.022" iyz="0.0" izz="0.04"/>
    </inertial>
  </link>
  
  <joint name="base_to_rwheel" type="continuous">
    <parent link="base_link"/>
    <child link="rwheel"/>
    <axis xyz="0.0 0.0 1.0"/>
    <limit effort="100.0" velocity="100.0"/>
    <joint_properties damping="0.0" friction="0.0"/>
    <origin xyz="0 -0.25 0.2" rpy="-1.5708 0 0"/>
  </joint>

<!-- Balance wheel -->

  <link name="fwheel_attach">
    <visual>
      <geometry>
        <box size="0.05 0.05 0.1"/>
      </geometry>
      <origin rpy="0 0 0" xyz="0 0 0"/>
      <material name="lime">
        <color rgba="0.3 0.6 0 1"/>
      </material>
    </visual>
    <collision>
      <geometry>
        <box size="0.05 0.05 0.1"/>
      </geometry>
      <origin rpy="0 0 0" xyz="0 0 0"/>
    </collision>
    <inertial>
      <origin xyz="0.0 0.0 0.0" rpy="0.0 0.0 0.0"/>
      <mass value="0.5"/>
      <inertia ixx="0.0005" ixy="0.0" ixz="0.0" iyy="0.0005" iyz="0.0" izz="0.0002"/>
    </inertial>
    
  </link>
  
  <joint name="base_to_fattach" type="fixed">
    <parent link="base_link"/>
    <child link="fwheel_attach"/>
    <origin xyz="0.225 0 0.1" rpy="0 0 0"/>
  </joint>
  
  <link name="fwheel">
    <visual>
      <geometry>
        <sphere radius="0.025"/>
      </geometry>
      <origin rpy="0 0 0" xyz="0 0 0"/>
      <material name="black">
        <color rgba="0 0 0 1"/>
      </material>
    </visual>
    <collision>
      <geometry>
        <sphere radius="0.025"/>
      </geometry>
      <origin rpy="0 0 0" xyz="0 0 0"/>
    </collision>
    <inertial>
      <origin xyz="0.0 0.0 0.0" rpy="0.0 0.0 0.0"/>
      <mass value="0.5"/>
      <inertia ixx="0.0001" ixy="0.0" ixz="0.0" iyy="0.0001" iyz="0.0" izz="0.0001"/>
    </inertial>
    
  </link>
  
  <joint name="fwheel_attach_to_fwheel" type="continuous">
    <parent link="fwheel_attach"/>
    <child link="fwheel"/>
    <origin xyz="0 0 -0.075" rpy="0 0 0"/>
    <axis xyz="1.0 1.0 1.0"/>
    <limit effort="100.0" velocity="100.0"/>
    <joint_properties damping="0.0" friction="0.0"/>
  </joint>

  <link name="bwheel_attach">
    <visual>
      <geometry>
        <box size="0.05 0.05 0.1"/>
      </geometry>
      <origin rpy="0 0 0" xyz="0 0 0"/>
      <material name="lime">
        <color rgba="0.3 0.6 0 1"/>
      </material>
    </visual>
    <collision>
      <geometry>
        <box size="0.05 0.05 0.1"/>
      </geometry>
      <origin rpy="0 0 0" xyz="0 0 0"/>
    </collision>
    <inertial>
      <origin xyz="0.0 0.0 0.0" rpy="0.0 0.0 0.0"/>
      <mass value="0.5"/>
      <inertia ixx="0.0005" ixy="0.0" ixz="0.0" iyy="0.0005" iyz="0.0" izz="0.0002"/>
    </inertial>
    
  </link>
  
  <joint name="base_to_battach" type="fixed">
    <parent link="base_link"/>
    <child link="bwheel_attach"/>
    <origin xyz="-0.225 0 0.1" rpy="0 0 0"/>
  </joint>
  
  <link name="bwheel">
    <visual>
      <geometry>
        <sphere radius="0.025"/>
      </geometry>
      <origin rpy="0 0 0" xyz="0 0 0"/>
      <material name="black">
        <color rgba="0 0 0 1"/>
      </material>
    </visual>
    <collision>
      <geometry>
        <sphere radius="0.025"/>
      </geometry>
      <origin rpy="0 0 0" xyz="0 0 0"/>
    </collision>
    <inertial>
      <origin xyz="0.0 0.0 0.0" rpy="0.0 0.0 0.0"/>
      <mass value="0.5"/>
      <inertia ixx="0.0001" ixy="0.0" ixz="0.0" iyy="0.0001" iyz="0.0" izz="0.0001"/>
    </inertial>
    
  </link>
  
  <joint name="bwheel_attach_to_bwheel" type="continuous">
    <parent link="bwheel_attach"/>
    <child link="bwheel"/>
    <origin xyz="0 0 -0.075" rpy="0 0 0"/>
    <axis xyz="1.0 1.0 1.0"/>
    <limit effort="100.0" velocity="100.0"/>
    <joint_properties damping="0.0" friction="0.0"/>
  </joint>

<!-- Camera -->

  <link name="camera">
    <visual>
      <geometry>
        <cylinder radius="0.025" length="0.3"/>
      </geometry>
      <origin rpy="0 0 0" xyz="0 0 0"/>
      <material name="black">
        <color rgba="0 0 0 1"/>
      </material>
    </visual>
    <collision>
      <geometry>
        <cylinder radius="0.025" length="0.3"/>
      </geometry>
      <origin rpy="0 0 0" xyz="0 0 0"/>
    </collision>
    <inertial>
      <origin xyz="0.0 0.0 0.0" rpy="0.0 0.0 0.0"/>
      <mass value="0.1"/>
      <inertia ixx="0.0008" ixy="0.0" ixz="0.0" iyy="0.0008" iyz="0.0" izz="0.00003"/>
    </inertial>
    
  </link>
  
  <joint name="head_to_camera" type="revolute">
    <parent link="head"/>
    <child link="camera"/>
    <origin xyz="0.175 0 0.075" rpy="1.5708 0 0"/>
    <axis xyz="0.0 0.0 1.0"/>
    <limit lower="-1.0472" upper="1.0472" effort="1000.0" velocity="0.5"/>
  </joint>

    <link name="lens">
    <visual>
      <geometry>
        <box size="0.01 0.025 0.025"/>
      </geometry>
      <origin rpy="0 0 0" xyz="0 0 0"/>
      <material name="white">
        <color rgba="1 1 1 1"/>
      </material>
    </visual>
    <collision>
      <geometry>
        <box size="0.1 0.01 0.1"/>
      </geometry>
      <origin rpy="0 0 0" xyz="0 0 0"/>
    </collision>
    <inertial>
      <origin xyz="0.0 0.0 0.0" rpy="0.0 0.0 0.0"/>
      <mass value="0.05"/>
      <inertia ixx="0.000005" ixy="0.0" ixz="0.0" iyy="0.000003" iyz="0.0" izz="0.000003"/>
    </inertial>
    
  </link>

  <joint name="camera_to_lens" type="fixed">
    <parent link="camera"/>
    <child link="lens"/>
    <origin xyz="0.03 0 0" rpy="-1.5708 0 0"/>
  </joint>

  <joint name="hokuyo_joint" type="fixed">
    <axis xyz="0 1 0" />
    <origin xyz="0.2275 0 0.2" rpy="0 0 0"/>
    <parent link="base_link"/>
    <child link="hokuyo_link"/>
  </joint>

  <!-- Hokuyo Laser -->
  <link name="hokuyo_link">
    <collision>
      <origin xyz="0 0 0" rpy="0 0 0"/>
      <geometry>
    <box size="0.1 0.1 0.1"/>
      </geometry>
    </collision>

    <visual>
      <origin xyz="0 0 0" rpy="0 0 0"/>
      <geometry>
        <mesh filename="package://differential_drive/mesh/hokuyo.dae"/>
      </geometry>
    </visual>

    <inertial>
      <mass value="1e-5" />
      <origin xyz="0 0 0" rpy="0 0 0"/>
      <inertia ixx="1e-6" ixy="0" ixz="0" iyy="1e-6" iyz="0" izz="1e-6" />
    </inertial>
  </link>

    <!-- transmission -->
  <transmission name="cam_trans">
    <type>transmission_interface/SimpleTransmission</type>
    <actuator name="motor1">
      <mechanicalReduction>1</mechanicalReduction>
    </actuator>
    <joint name="head_to_camera">
      <hardwareInterface>hardware_interface/EffortJointInterface</hardwareInterface>
    </joint>
  </transmission>
  
  <transmission name="head_trans">
    <type>transmission_interface/SimpleTransmission</type>
    <actuator name="motor2">
      <mechanicalReduction>1</mechanicalReduction>
    </actuator>
    <joint name="body_to_head">
      <hardwareInterface>hardware_interface/EffortJointInterface</hardwareInterface>
    </joint>
  </transmission>

  <transmission name="left_wheel_transmission">
    <type>transmission_interface/SimpleTransmission</type>
    <joint name="base_to_lwheel">
      <hardwareInterface>hardware_interface/VelocityJointInterface</hardwareInterface>  
    </joint>
    <actuator name="left_wheel_actuator">
      <mechanicalReduction>10</mechanicalReduction>
      <hardwareInterface>VelocityJointInterface</hardwareInterface>
    </actuator>
  </transmission>

  <transmission name="right_wheel_transmission">
    <type>transmission_interface/SimpleTransmission</type>
    <joint name="base_to_rwheel">
      <hardwareInterface>hardware_interface/VelocityJointInterface</hardwareInterface>  
    </joint>
    <actuator name="right_wheel_actuator">
      <mechanicalReduction>10</mechanicalReduction>
      <hardwareInterface>VelocityJointInterface</hardwareInterface>
    </actuator>
  </transmission>

   <transmission name="front_wheel_transmission">
    <type>transmission_interface/SimpleTransmission</type>
    <joint name="fwheel_attach_to_fwheel">
      <hardwareInterface>hardware_interface/VelocityJointInterface</hardwareInterface>  
    </joint>
    <actuator name="front_wheel_actuator">
      <mechanicalReduction>1</mechanicalReduction>
      <hardwareInterface>VelocityJointInterface</hardwareInterface>
    </actuator>
  </transmission>

   <transmission name="back_wheel_transmission">
    <type>transmission_interface/SimpleTransmission</type>
    <joint name="bwheel_attach_to_bwheel">
      <hardwareInterface>hardware_interface/VelocityJointInterface</hardwareInterface>  
    </joint>
    <actuator name="back_wheel_actuator">
      <mechanicalReduction>1</mechanicalReduction>
      <hardwareInterface>VelocityJointInterface</hardwareInterface>
    </actuator>
  </transmission>

  <!-- camera -->
  <gazebo reference="lens">
    <sensor type="camera" name="camera1">
      <update_rate>30.0</update_rate>
      <camera name="head">
        <horizontal_fov>1.3962634</horizontal_fov>
        <image>
          <width>800</width>
          <height>800</height>
          <format>R8G8B8</format>
        </image>
        <clip>
          <near>0.02</near>
          <far>300</far>
        </clip>
      </camera>
      <plugin name="camera_controller" filename="libgazebo_ros_camera.so">
        <alwaysOn>true</alwaysOn>
        <updateRate>0.0</updateRate>
        <cameraName>robot/camera1</cameraName>
        <imageTopicName>image_raw</imageTopicName>
        <cameraInfoTopicName>camera_info</cameraInfoTopicName>
        <frameName>lens</frameName>
        <hackBaseline>0.07</hackBaseline>
        <distortionK1>0.0</distortionK1>
        <distortionK2>0.0</distortionK2>
        <distortionK3>0.0</distortionK3>
        <distortionT1>0.0</distortionT1>
        <distortionT2>0.0</distortionT2>
      </plugin>
    </sensor>
  </gazebo>

  <!-- ROS Control plugin for Gazebo -->
  <gazebo>
    <plugin name="gazebo_ros_control" filename="libgazebo_ros_control.so"/>
  </gazebo>

    <!-- hokuyo -->
  <gazebo reference="hokuyo_link">
    <sensor type="gpu_ray" name="head_hokuyo_sensor">
      <pose>0 0 0 0 0 0</pose>
      <visualize>false</visualize>
      <update_rate>50</update_rate>
      <ray>
        <scan>
          <horizontal>
            <samples>720</samples>
            <resolution>1</resolution>
            <min_angle>-1.570796</min_angle>
            <max_angle>1.570796</max_angle>
          </horizontal>
        </scan>
        <range>
          <min>0.10</min>
          <max>30.0</max>
          <resolution>0.01</resolution>
        </range>
        <noise>
          <type>gaussian</type>
          <!-- Noise parameters based on published spec for Hokuyo laser
               achieving "+-30mm" accuracy at range < 10m.  A mean of 0.0m and
               stddev of 0.01m will put 99.7% of samples within 0.03m of the true
               reading. -->
          <mean>0.0</mean>
          <stddev>0.01</stddev>
        </noise>
      </ray>
      <plugin name="gazebo_ros_head_hokuyo_controller" filename="libgazebo_ros_gpu_laser.so">
        <topicName>/laser/scan</topicName>
        <frameName>hokuyo_link</frameName>
      </plugin>
    </sensor>
  </gazebo>

<!-- Material -->

  <gazebo reference="base_link">
    <material>
      Gazebo/Green
    </material>
    <mu1>0.1</mu1>
    <mu2>0.1</mu2>
  </gazebo>
  <gazebo reference="body">
    <material>
      Gazebo/Green
    </material>
    <mu1>0.1</mu1>
    <mu2>0.1</mu2>
  </gazebo>
  <gazebo reference="head">
    <material>
      Gazebo/Green
    </material>
    <mu1>0.1</mu1>
    <mu2>0.1</mu2>
  </gazebo>
  <gazebo reference="fwheel_attach">
    <material>
      Gazebo/Green
    </material>
    <mu1>0.1</mu1>
    <mu2>0.1</mu2>
  </gazebo>
  <gazebo reference="bwheel_attach">
    <material>
      Gazebo/Green
    </material>
    <mu1>0.1</mu1>
    <mu2>0.1</mu2>
  </gazebo>
  <gazebo reference="fwheel">
    <material>
      Gazebo/Black
    </material>
    <mu1>0.1</mu1>
    <mu2>0.1</mu2>
  </gazebo>
  <gazebo reference="bwheel">
    <material>
      Gazebo/Black
    </material>
    <mu1>0.1</mu1>
    <mu2>0.1</mu2>
  </gazebo>
  <gazebo reference="lwheel">
    <material>
      Gazebo/Black
    </material>
    <mu1>2</mu1>
    <mu2>2</mu2>
  </gazebo>
  <gazebo reference="rwheel">
    <material>
      Gazebo/Black
    </material>
    <mu1>2</mu1>
    <mu2>2</mu2>
  </gazebo>
  <gazebo reference="camera">
    <material>
      Gazebo/Black
    </material>
    <mu1>0.1</mu1>
    <mu2>0.1</mu2>
  </gazebo>
  <gazebo reference="lens">
    <material>
      Gazebo/Black
    </material>
    <mu1>0.1</mu1>
    <mu2>0.1</mu2>
  </gazebo>
  <gazebo reference="hokuyo_link">
    <mu1>0.1</mu1>
    <mu2>0.1</mu2>
  </gazebo>
</robot>